<?xml version="1.0" ?>
<!-- =================================================================================== -->
<!-- |    This document was autogenerated by xacro from taurusbot.urdf.xacro           | -->
<!-- |    EDITING THIS FILE BY HAND IS NOT RECOMMENDED                                 | -->
<!-- =================================================================================== -->
<robot name="taurusbot" xmlns:xacro="http://www.ros.org/wiki/xacro">
  <!-- #################### versions without origin #################### -->
  <link name="base_link">
    <visual>
      <geometry>
        <box size="0.8255 0.6223 0.2159"/>
      </geometry>
      <material name="silver">
        <color rgba="0.75 0.75 0.75 1"/>
      </material>
    </visual>
    <collision>
      <geometry>
        <box size="0.8255 0.6223 0.2159"/>
      </geometry>
    </collision>
    <inertial>
      <mass value="200.0"/>
      <origin xyz="0 0 0"/>
      <inertia ixx="7.23116544087" ixy="0.0" ixz="0.0" iyy="12.1343794796" iyz="0.0" izz="17.8117852086"/>
    </inertial>
  </link>
  <joint name="base_to_motor_joint" type="fixed">
    <axis xyz="0 0 0"/>
    <parent link="base_link"/>
    <child link="motor"/>
    <origin rpy="0 0 0" xyz="0.0762 0 -0.1143"/>
  </joint>
  <link name="motor">
    <visual>
      <geometry>
        <box size="0.1524 0.6096 0.1397"/>
      </geometry>
      <material name="silver">
        <color rgba="0.75 0.75 0.75 1"/>
      </material>
    </visual>
    <collision>
      <geometry>
        <box size="0.1524 0.6096 0.1397"/>
      </geometry>
    </collision>
    <inertial>
      <mass value="300.0"/>
      <origin xyz="0 0 0"/>
      <inertia ixx="9.7477473509" ixy="0.0" ixz="0.0" iyy="1.06854582258" iyz="0.0" izz="9.8404890638"/>
    </inertial>
  </link>
  <joint name="left_wheel_joint" type="continuous">
    <axis xyz="0 0 1"/>
    <parent link="motor"/>
    <child link="motor_left_wheel"/>
    <origin rpy="-1.5708 0 0" xyz="0 0.3048 0"/>
  </joint>
  <joint name="right_wheel_joint" type="continuous">
    <axis xyz="0 0 1"/>
    <parent link="motor"/>
    <child link="motor_right_wheel"/>
    <origin rpy="-1.5708 0 0" xyz="0 -0.3048 0"/>
  </joint>
  <link name="motor_right_wheel">
    <visual>
      <geometry>
        <cylinder length="0.0889" radius="0.127"/>
      </geometry>
      <material name="black">
        <color rgba="0 0 0 1"/>
      </material>
    </visual>
    <collision>
      <geometry>
        <cylinder length="0.0889" radius="0.127"/>
      </geometry>
    </collision>
    <inertial>
      <mass value="80.0"/>
      <origin xyz="0 0 0"/>
      <inertia ixx="0.375267916559" ixy="0.0" ixz="0.0" iyy="0.375267916559" iyz="0.0" izz="0.64516"/>
    </inertial>
  </link>
  <link name="motor_left_wheel">
    <visual>
      <geometry>
        <cylinder length="0.0889" radius="0.127"/>
      </geometry>
      <material name="black">
        <color rgba="0 0 0 1"/>
      </material>
    </visual>
    <collision>
      <geometry>
        <cylinder length="0.0889" radius="0.127"/>
      </geometry>
    </collision>
    <inertial>
      <mass value="80.0"/>
      <origin xyz="0 0 0"/>
      <inertia ixx="0.375267916559" ixy="0.0" ixz="0.0" iyy="0.375267916559" iyz="0.0" izz="0.64516"/>
    </inertial>
  </link>
  <joint name="base_to_rearplatform" type="fixed">
    <axis xyz="0 0 0"/>
    <parent link="base_link"/>
    <child link="rearplatform"/>
    <origin rpy="0 0 0" xyz="-0.53975 0 -0.12065"/>
  </joint>
  <link name="rearplatform">
    <visual>
      <geometry>
        <box size="0.254 0.4445 0.0254"/>
      </geometry>
      <material name="silver">
        <color rgba="0.75 0.75 0.75 1"/>
      </material>
    </visual>
    <collision>
      <geometry>
        <box size="0.254 0.4445 0.0254"/>
      </geometry>
    </collision>
    <inertial>
      <mass value="10.0"/>
      <origin xyz="0 0 0"/>
      <inertia ixx="0.165187775592" ixy="0.0" ixz="0.0" iyy="0.0543009449463" iyz="0.0" izz="0.218413454301"/>
    </inertial>
  </link>
  <joint name="rearplatform_to_rlwCaster" type="fixed">
    <axis xyz="0 0 0"/>
    <parent link="rearplatform"/>
    <child link="rlwCaster"/>
    <origin rpy="0 0 0" xyz="0 0.20955 -0.0254"/>
  </joint>
  <link name="rlwCaster">
    <visual>
      <geometry>
        <box size="0.0254 0.0254 0.0508"/>
      </geometry>
      <material name="silver">
        <color rgba="0.75 0.75 0.75 1"/>
      </material>
    </visual>
    <collision>
      <geometry>
        <box size="0.0254 0.0254 0.0508"/>
      </geometry>
    </collision>
    <inertial>
      <mass value="7.0"/>
      <origin xyz="0 0 0"/>
      <inertia ixx="0.00188171591398" ixy="0.0" ixz="0.0" iyy="0.00188171591398" iyz="0.0" izz="0.000752686365592"/>
    </inertial>
  </link>
  <joint name="rlwCaster to rlwJointCaster" type="continuous">
    <axis xyz="0 0 1"/>
    <parent link="rlwCaster"/>
    <child link="rlwJointCaster"/>
    <origin rpy="0 0 0" xyz="0 0.0 -0.0254"/>
  </joint>
  <link name="rlwJointCaster">
    <visual>
      <geometry>
        <cylinder length="0.03" radius="0.015"/>
      </geometry>
      <material name="black">
        <color rgba="0 0 0 1"/>
      </material>
    </visual>
    <collision>
      <geometry>
        <cylinder length="0.03" radius="0.015"/>
      </geometry>
    </collision>
    <inertial>
      <mass value="8.0"/>
      <origin xyz="0 0 0"/>
      <inertia ixx="0.00104999958" ixy="0.0" ixz="0.0" iyy="0.00104999958" iyz="0.0" izz="0.0009"/>
    </inertial>
  </link>
  <joint name="rlwJointCaster to rlw" type="continuous">
    <axis xyz="0 0 1"/>
    <parent link="rlwJointCaster"/>
    <child link="rlw"/>
    <origin rpy="-1.5708 0 0" xyz="0 0.0 -0.0254"/>
  </joint>
  <link name="rlw">
    <visual>
      <geometry>
        <cylinder length="0.05" radius="0.035"/>
      </geometry>
      <material name="black">
        <color rgba="0 0 0 1"/>
      </material>
    </visual>
    <collision>
      <geometry>
        <cylinder length="0.05" radius="0.035"/>
      </geometry>
    </collision>
    <inertial>
      <mass value="16.0"/>
      <origin xyz="0 0 0"/>
      <inertia ixx="0.00823333004" ixy="0.0" ixz="0.0" iyy="0.00823333004" iyz="0.0" izz="0.0098"/>
    </inertial>
  </link>
  <joint name="rearplatform_to_rrwCaster" type="fixed">
    <axis xyz="0 0 0"/>
    <parent link="rearplatform"/>
    <child link="rrwCaster"/>
    <origin rpy="0 0 0" xyz="0 -0.20955 -0.0254"/>
  </joint>
  <link name="rrwCaster">
    <visual>
      <geometry>
        <box size="0.0254 -0.0254 0.0508"/>
      </geometry>
      <material name="silver">
        <color rgba="0.75 0.75 0.75 1"/>
      </material>
    </visual>
    <collision>
      <geometry>
        <box size="0.0254 -0.0254 0.0508"/>
      </geometry>
    </collision>
    <inertial>
      <mass value="7.0"/>
      <origin xyz="0 0 0"/>
      <inertia ixx="0.00188171591398" ixy="0.0" ixz="0.0" iyy="0.00188171591398" iyz="0.0" izz="0.000752686365592"/>
    </inertial>
  </link>
  <joint name="rrwCaster to rrwJointCaster" type="continuous">
    <axis xyz="0 0 1"/>
    <parent link="rrwCaster"/>
    <child link="rrwJointCaster"/>
    <origin rpy="0 0 0" xyz="0 0.0 -0.0254"/>
  </joint>
  <link name="rrwJointCaster">
    <visual>
      <geometry>
        <cylinder length="0.03" radius="0.015"/>
      </geometry>
      <material name="black">
        <color rgba="0 0 0 1"/>
      </material>
    </visual>
    <collision>
      <geometry>
        <cylinder length="0.03" radius="0.015"/>
      </geometry>
    </collision>
    <inertial>
      <mass value="8.0"/>
      <origin xyz="0 0 0"/>
      <inertia ixx="0.00104999958" ixy="0.0" ixz="0.0" iyy="0.00104999958" iyz="0.0" izz="0.0009"/>
    </inertial>
  </link>
  <joint name="rrwJointCaster to rrw" type="continuous">
    <axis xyz="0 0 1"/>
    <parent link="rrwJointCaster"/>
    <child link="rrw"/>
    <origin rpy="1.5708 0 0" xyz="0 0.0 -0.0254"/>
  </joint>
  <link name="rrw">
    <visual>
      <geometry>
        <cylinder length="0.05" radius="0.035"/>
      </geometry>
      <material name="black">
        <color rgba="0 0 0 1"/>
      </material>
    </visual>
    <collision>
      <geometry>
        <cylinder length="0.05" radius="0.035"/>
      </geometry>
    </collision>
    <inertial>
      <mass value="16.0"/>
      <origin xyz="0 0 0"/>
      <inertia ixx="0.00823333004" ixy="0.0" ixz="0.0" iyy="0.00823333004" iyz="0.0" izz="0.0098"/>
    </inertial>
  </link>
  <gazebo>
    <plugin filename="libgazebo_ros_diff_drive.so" name="differential_drive_controller">
      <leftJoint>left_wheel_joint</leftJoint>
      <rightJoint>right_wheel_joint</rightJoint>
      <robotBaseFrame>base_link</robotBaseFrame>
      <wheelSeparation>0.5207</wheelSeparation>
      <wheelDiameter>0.254</wheelDiameter>
      <publishWheelJointState>true</publishWheelJointState>
      <legacyMode>false</legacyMode>
      <wheelTorque>180</wheelTorque>
    </plugin>
  </gazebo>
</robot>
