<?xml version="1.0"?>
<robot name="taurusbot">

  <link name="base_link">
    <visual>
      <geometry>
        <box size="0.8255 0.6223 0.2159"/>
      </geometry>
      <material name="silver">
        <color rgba="0.75 0.75 0.75 1"/>
      </material>
    </visual>
    <collision>
     <geometry>
      <box size="0.8255 0.6223 0.2159"/>
     </geometry>
    </collision>

    <inertial>
      <mass value="2.0"/>
      <inertia ixx="0.015" iyy="0.0375" izz="0.0375"
               ixy="0" ixz="0" iyz="0"/>
    </inertial>

  </link>

	<joint name="base_to_motor_joint" type="fixed">
    <axis xyz="0 0 0"/>
    <parent link="base_link"/>
    <child link="motor"/>
    <origin rpy="0 0 0" xyz="0.0762 0 -0.1143"/>
	</joint>

	<link name="motor">
	<visual>
			<geometry>
				<box size="0.1524 0.6096 0.1397"/>
			</geometry>
			      <material name="silver">
			        <color rgba="0.75 0.75 0.75 1"/>
      			 </material>
		</visual>
		
		<collision>
     <geometry>
      <box size="0.1524 0.6096 0.1397"/>
     </geometry>
    </collision>

    <inertial>
      <mass value="10.0"/>
      <inertia ixx="0.015" iyy="0.0375" izz="0.0375"
               ixy="0" ixz="0" iyz="0"/>
    </inertial>

		
	</link>

	<joint name="left_wheel_joint" type="continuous">
  	  <axis xyz="0 0 1"/>
 		  <parent link="motor"/>
  	  <child link="motor_left_wheel"/>
  	  <origin rpy="-1.5708 0 0" xyz="0 0.3048 0"/>
		</joint>

	<joint name="right_wheel_joint" type="continuous">
  	  <axis xyz="0 0 1"/>
 		  <parent link="motor"/>
  	  <child link="motor_right_wheel"/>
  	  <origin rpy="-1.5708 0 0" xyz="0 -0.3048 0"/>
		</joint>
	



  <link name="motor_right_wheel">
    <visual>
      <geometry>
        <cylinder length="0.0889" radius="0.127"/>
      </geometry>
      <material name="black">
        <color rgba="0 0 0 1"/>
      </material>
    </visual>
    
    <collision>
     <geometry>
        <cylinder length="0.0889" radius="0.127"/>
      </geometry>
    </collision>

   <inertial>
      <mass value="2"/>
      <inertia ixx="5.1458e-5" iyy="5.1458e-5" izz="6.125e-5"
               ixy="0" ixz="0" iyz="0"/>
    </inertial>
    
  </link>

  <link name="motor_left_wheel">
    <visual>
      <geometry>
        <cylinder length="0.0889" radius="0.127"/>
      </geometry>
      <material name="black">
        <color rgba="0 0 0 1"/>
      </material>
    </visual>
    
    
        <collision>
     <geometry>
        <cylinder length="0.0889" radius="0.127"/>
      </geometry>
    </collision>
    
       <inertial>
      <mass value="2"/>
      <inertia ixx="5.1458e-5" iyy="5.1458e-5" izz="6.125e-5"
               ixy="0" ixz="0" iyz="0"/>
    </inertial>
    
  </link>

	<joint name="base_to_rearplatform" type="fixed">
    <axis xyz="0 0 0"/>
    <parent link="base_link"/>
    <child link="rearplatform"/>
    <origin rpy="0 0 0" xyz="-0.53975 0 -0.12065"/>
	</joint>


	<link name="rearplatform">
	<visual>
			<geometry>
				<box size="0.254 0.4445 0.0254"/>
			</geometry>
			      <material name="silver">
			        <color rgba="0.75 0.75 0.75 1"/>
      			 </material>
		</visual>
		
		        <collision>
     <geometry>
				<box size="0.254 0.4445 0.0254"/>
      </geometry>
    </collision>
    
        <inertial>
      <mass value="1.0"/>
      <inertia ixx="0.015" iyy="0.0375" izz="0.0375"
               ixy="0" ixz="0" iyz="0"/>
    </inertial>
		
		
	</link>


	<joint name="rearplatform_to_rlwCaster" type="fixed">
    <axis xyz="0 0 0"/>
    <parent link="rearplatform"/>
    <child link="rlwCaster"/>
    <origin rpy="0 0 0" xyz="0 0.20955 -0.0254"/>
	</joint>


	
			<link name="rlwCaster">
	<visual>
			<geometry>
				<box size="0.0254 0.0254 0.0508"/>
			</geometry>
			      <material name="silver">
			        <color rgba="0.75 0.75 0.75 1"/>
      			 </material>
		</visual>
		
				        <collision>
     <geometry>
				<box size="0.0254 0.0254 0.0508"/>
      </geometry>
    </collision>
    
         <inertial>
      <mass value="2.0"/>
      <inertia ixx="0.015" iyy="0.0375" izz="0.0375"
               ixy="0" ixz="0" iyz="0"/>
    </inertial>
		
		
	</link>
	
	
	<joint name="rlwCaster to rlw" type="continuous">
    <axis xyz="0 1 0"/>
    <parent link="rlwCaster"/>
    <child link="rlw"/>
    <origin rpy="-1.5708 0 0" xyz="0 0.0 -0.0254"/>
	</joint>


	  <link name="rlw">
    <visual>
      <geometry>
        <cylinder length="0.03175" radius="0.0635"/>
      </geometry>
      <material name="black">
        <color rgba="0 0 0 1"/>
      </material>
    </visual>    
    
      <collision>
     <geometry>
        <cylinder length="0.03175" radius="0.0635"/>
     </geometry>
    </collision>
    
      <inertial>
      <mass value="7"/>
      <inertia ixx="5.1458e-5" iyy="5.1458e-5" izz="6.125e-5"
               ixy="0" ixz="0" iyz="0"/>
    </inertial>
    
  </link>
	


	
	
		<joint name="rearplatform_to_rrwCaster" type="fixed">
    <axis xyz="0 0 0"/>
    <parent link="rearplatform"/>
    <child link="rrwCaster"/>
    <origin rpy="0 0 0" xyz="0 -0.20955 -0.0254"/>
	</joint>
	

	
	<link name="rrwCaster">
	<visual>
			<geometry>
				<box size="0.0254 -0.0254 0.0508"/>
			</geometry>
			      <material name="silver">
			        <color rgba="0.75 0.75 0.75 1"/>
      			 </material>
		</visual>
		
		    <collision>
     <geometry>
				<box size="0.0254 -0.0254 0.0508"/>
     </geometry>
    </collision>
    
             <inertial>
      <mass value="2.0"/>
      <inertia ixx="0.015" iyy="0.0375" izz="0.0375"
               ixy="0" ixz="0" iyz="0"/>
    </inertial>
		
	</link>
	
	
	
		
	<joint name="rrwCaster to rlw" type="continuous">
    <axis xyz="0 1 0"/>
    <parent link="rrwCaster"/>
    <child link="rrw"/>
    <origin rpy="-1.5708 0 0" xyz="0 0.0 -0.0254"/>
	</joint>


	  <link name="rrw">
    <visual>
      <geometry>
        <cylinder length="0.03175" radius="0.0635"/>
      </geometry>
      <material name="black">
        <color rgba="0 0 0 1"/>
      </material>
    </visual>    
    
        <collision>
     <geometry>
        <cylinder length="0.03175" radius="0.0635"/>
     </geometry>
    </collision>
    
       <inertial>
      <mass value="7"/>
      <inertia ixx="5.1458e-5" iyy="5.1458e-5" izz="6.125e-5"
               ixy="0" ixz="0" iyz="0"/>
    </inertial>
    
    
  </link>
	

<gazebo>
    <plugin name="differential_drive_controller"
            filename="libgazebo_ros_diff_drive.so">
      <leftJoint>left_wheel_joint</leftJoint>
      <rightJoint>right_wheel_joint</rightJoint>
      <robotBaseFrame>base_link</robotBaseFrame>
      <wheelSeparation>0.5207</wheelSeparation>
      <wheelDiameter>0.254</wheelDiameter>
      <publishWheelJointState>true</publishWheelJointState>
    </plugin>
  </gazebo>

</robot>

